Tests run by: fkjldsöa
Tests run at: 2023-01-26_17-36-05
Test suite: 
<unittest.suite.TestSuite tests=[<tests.utility.test_data_functions.Data_Functions_Tester testMethod=test_add_location>, <tests.utility.test_data_functions.Data_Functions_Tester testMethod=test_add_location_to_occ_csv>, <tests.utility.test_data_functions.Data_Functions_Tester testMethod=test_add_url_to_json>, <tests.utility.test_data_functions.Data_Functions_Tester testMethod=test_check_location_exists>, <tests.utility.test_data_functions.Data_Functions_Tester testMethod=test_check_url>, <tests.utility.test_data_functions.Data_Functions_Tester testMethod=test_get_dict_from_url>, <tests.utility.test_data_functions.Data_Functions_Tester testMethod=test_get_lat_lon_from_url>, <tests.utility.test_data_functions.Data_Functions_Tester testMethod=test_get_response_from_url>, <tests.utility.test_data_functions.Data_Functions_Tester testMethod=test_remove_location>, <tests.utility.test_data_functions.Data_Functions_Tester testMethod=test_remove_location_from_csv>, <tests.utility.test_data_functions.Data_Functions_Tester testMethod=test_remove_location_from_json>, <tests.utility.test_data_functions.Data_Functions_Tester testMethod=test_update_characteristics_in_csv>, <tests.utility.test_data_functions.Data_Functions_Tester testMethod=test_update_location_occupancy>, <tests.utility.test_data_functions.Data_Functions_Tester testMethod=test_update_url_in_json>]>

Test results:
E............F
======================================================================
ERROR: test_add_location (tests.utility.test_data_functions.Data_Functions_Tester)
----------------------------------------------------------------------
Traceback (most recent call last):
  File "S:\Dashboard\tests\utility\test_data_functions.py", line 28, in test_add_location
    add_location(self.example_dict, "https://www.google.com")
  File "S:\Dashboard\App\utility\data_functions.py", line 68, in add_location
    raise Exception('The location {} already exists'.format(location))  # Raise an exception
Exception: The location location name already exists

======================================================================
FAIL: test_update_url_in_json (tests.utility.test_data_functions.Data_Functions_Tester)
----------------------------------------------------------------------
Traceback (most recent call last):
  File "S:\Dashboard\tests\utility\test_data_functions.py", line 99, in test_update_url_in_json
    self.assertRaises(Exception, update_url_in_json, "djklfwsanfold", "test")
AssertionError: Exception not raised by update_url_in_json

----------------------------------------------------------------------
Ran 14 tests in 0.014s

FAILED (failures=1, errors=1)
