Tests run by: Tim K
Tests run at: 2023-02-03_22-33-41
Test suite: 
<unittest.suite.TestSuite tests=[<tests.utility.test_data_functions.Data_Functions_Tester testMethod=test_add_location>, <tests.utility.test_data_functions.Data_Functions_Tester testMethod=test_add_location_to_occ_csv>, <tests.utility.test_data_functions.Data_Functions_Tester testMethod=test_add_url_to_json>, <tests.utility.test_data_functions.Data_Functions_Tester testMethod=test_check_location_exists>, <tests.utility.test_data_functions.Data_Functions_Tester testMethod=test_check_url>, <tests.utility.test_data_functions.Data_Functions_Tester testMethod=test_get_dict_from_url>, <tests.utility.test_data_functions.Data_Functions_Tester testMethod=test_get_lat_lon_from_url>, <tests.utility.test_data_functions.Data_Functions_Tester testMethod=test_get_response_from_url>, <tests.utility.test_data_functions.Data_Functions_Tester testMethod=test_remove_location>, <tests.utility.test_data_functions.Data_Functions_Tester testMethod=test_remove_location_from_csv>, <tests.utility.test_data_functions.Data_Functions_Tester testMethod=test_remove_location_from_json>, <tests.utility.test_data_functions.Data_Functions_Tester testMethod=test_update_characteristics_in_csv>, <tests.utility.test_data_functions.Data_Functions_Tester testMethod=test_update_location_occupancy>, <tests.utility.test_data_functions.Data_Functions_Tester testMethod=test_update_url_in_json>]>

Test results:
.......E......
======================================================================
ERROR: test_get_response_from_url (tests.utility.test_data_functions.Data_Functions_Tester)
----------------------------------------------------------------------
Traceback (most recent call last):
  File "s:\Dashboard\tests\utility\test_data_functions.py", line 144, in test_get_response_from_url
    get_response_from_url("Test")
  File "s:\Dashboard\App\utility\data_functions.py", line 450, in get_response_from_url
    r = requests.get(url, auth=(username, password))  # Send a request to the url using the username and password
  File "C:\Users\Tim-K\anaconda3\envs\bachelor_praktikum\lib\site-packages\requests\api.py", line 73, in get
    return request("get", url, params=params, **kwargs)
  File "C:\Users\Tim-K\anaconda3\envs\bachelor_praktikum\lib\site-packages\requests\api.py", line 59, in request
    return session.request(method=method, url=url, **kwargs)
  File "C:\Users\Tim-K\anaconda3\envs\bachelor_praktikum\lib\site-packages\requests\sessions.py", line 573, in request
    prep = self.prepare_request(req)
  File "C:\Users\Tim-K\anaconda3\envs\bachelor_praktikum\lib\site-packages\requests\sessions.py", line 484, in prepare_request
    p.prepare(
  File "C:\Users\Tim-K\anaconda3\envs\bachelor_praktikum\lib\site-packages\requests\models.py", line 368, in prepare
    self.prepare_url(url, params)
  File "C:\Users\Tim-K\anaconda3\envs\bachelor_praktikum\lib\site-packages\requests\models.py", line 439, in prepare_url
    raise MissingSchema(
requests.exceptions.MissingSchema: Invalid URL 'Test': No scheme supplied. Perhaps you meant http://Test?

----------------------------------------------------------------------
Ran 14 tests in 0.023s

FAILED (errors=1)
